Workbook

Sheet Items
A1: receipt_id | B1: line_no | C1: item | D1: amount_cad | E1: Code | F1: GST | G1: PST | H1: budget_category | I1: category_source | J1: raw_line
A2: 20260214_sobeys_363_95 | B2: 3 | C2: Oep Pic Med | D2: 6.49 | E2: C | F2: =IF(OR(E2="C",E2=""),0,D2*0.05) -> 0 | G2: =IF(OR(E2="C",E2=""),0,D2*0.07) -> 0 | H2: Groceries | I2: default | J2: GROCERY | $6.49
A3: 20260214_sobeys_363_95 | B3: 9 | C3: Oep Pic Med | D3: 6.49 | E3: C | F3: =IF(OR(E3="C",E3=""),0,D3*0.05) -> 0 | G3: =IF(OR(E3="C",E3=""),0,D3*0.07) -> 0 | H3: Groceries | I3: default | J3: Cep Pic Med | $6.49
A4: 20260214_sobeys_363_95 | C4: INSTANT SAVINGS | D4: -0.5 | F4: =IF(OR(E4="C",E4=""),0,D4*0.05) -> 0 | G4: =IF(OR(E4="C",E4=""),0,D4*0.07) -> 0
A5: 20260214_sobeys_363_95 | B5: 13 | C5: Pie Filling S/Berry | D5: 6.49 | E5: C | F5: =IF(OR(E5="C",E5=""),0,D5*0.05) -> 0 | G5: =IF(OR(E5="C",E5=""),0,D5*0.07) -> 0 | H5: Groceries | I5: exact | J5: Pie Filling S/Berry | $6.49
A6: 20260214_sobeys_363_95 | C6: INSTANT SAVINGS | D6: -0.5 | F6: =IF(OR(E6="C",E6=""),0,D6*0.05) -> 0 | G6: =IF(OR(E6="C",E6=""),0,D6*0.07) -> 0
A7: 20260214_sobeys_363_95 | B7: 23 | C7: Pie Filling S/Berry | D7: 6.49 | E7: C | F7: =IF(OR(E7="C",E7=""),0,D7*0.05) -> 0 | G7: =IF(OR(E7="C",E7=""),0,D7*0.07) -> 0 | H7: Groceries | I7: exact | J7: Pie Filling S/Berry | $6.49
A8: 20260214_sobeys_363_95 | B8: 37 | C8: Pretzels HoneyMustar | D8: 5.49 | E8: BC | F8: =IF(OR(E8="C",E8=""),0,D8*0.05) -> 0.2745 | G8: =IF(OR(E8="C",E8=""),0,D8*0.07) -> 0.3843 | H8: Groceries | I8: default | J8: Pretzels HoneyMustar | $1.00 |
A9: 20260214_sobeys_363_95 | B9: 43 | C9: Pretzel Cracker Rach | D9: 5.49 | E9: BC | F9: =IF(OR(E9="C",E9=""),0,D9*0.05) -> 0.2745 | G9: =IF(OR(E9="C",E9=""),0,D9*0.07) -> 0.3843 | H9: Groceries | I9: exact | J9: Pretzel Cracker Rahe | $5.49 BC
A10: 20260214_sobeys_363_95 | B10: 51 | C10: Chips Multigrain | D10: 5.29 | E10: BC | F10: =IF(OR(E10="C",E10=""),0,D10*0.05) -> 0.2645 | G10: =IF(OR(E10="C",E10=""),0,D10*0.07) -> 0.3703 | H10: Groceries | I10: exact | J10: Chips Multigrai | $5.29 BC
A11: 20260214_sobeys_363_95 | B11: 79 | C11: Chips Rstrnt Sty Lm | D11: 5.29 | E11: BC | F11: =IF(OR(E11="C",E11=""),0,D11*0.05) -> 0.2645 | G11: =IF(OR(E11="C",E11=""),0,D11*0.07) -> 0.3703 | H11: Groceries | I11: default | J11: C | $4.29
A12: 20260214_sobeys_363_95 | B12: 85 | C12: Dil Pkls Xt Grlc Snd | D12: 4.99 | E12: C | F12: =IF(OR(E12="C",E12=""),0,D12*0.05) -> 0 | G12: =IF(OR(E12="C",E12=""),0,D12*0.07) -> 0 | H12: Groceries | I12: default | J12: BC | $4.25
A13: 20260214_sobeys_363_95 | C13: Comp Quick Oats 1KG | D13: 4.79 | E13: C | F13: =IF(OR(E13="C",E13=""),0,D13*0.05) -> 0 | G13: =IF(OR(E13="C",E13=""),0,D13*0.07) -> 0
A14: 20260214_sobeys_363_95 | C14: Vinta Crackers | D14: 4.29 | E14: C | F14: =IF(OR(E14="C",E14=""),0,D14*0.05) -> 0 | G14: =IF(OR(E14="C",E14=""),0,D14*0.07) -> 0
A15: 20260214_sobeys_363_95 | B15: 97 | C15: Pepsi Zero | D15: 4.25 | E15: BC | F15: =IF(OR(E15="C",E15=""),0,D15*0.05) -> 0.2125 | G15: =IF(OR(E15="C",E15=""),0,D15*0.07) -> 0.2975 | H15: Groceries | I15: default | J15: Pepsi Zero | $4.25 BC
A16: 20260214_sobeys_363_95 | C16: EHC | D16: 0.12 | E16: BR | F16: =IF(OR(E16="C",E16=""),0,D16*0.05) -> 0.006 | G16: =IF(OR(E16="C",E16=""),0,D16*0.07) -> 0.0084
A17: 20260214_sobeys_363_95 | B17: 97 | C17: Pepsi Zero | D17: 4.25 | E17: BC | F17: =IF(OR(E17="C",E17=""),0,D17*0.05) -> 0.2125 | G17: =IF(OR(E17="C",E17=""),0,D17*0.07) -> 0.2975 | H17: Groceries | I17: default | J17: Pepsi Zero | $4.25 BC
A18: 20260214_sobeys_363_95 | C18: EHC | D18: 0.12 | E18: BR | F18: =IF(OR(E18="C",E18=""),0,D18*0.05) -> 0.006 | G18: =IF(OR(E18="C",E18=""),0,D18*0.07) -> 0.0084
A19: 20260214_sobeys_363_95 | B19: 107 | C19: Mexican Hot Sauce | D19: 3.69 | E19: C | F19: =IF(OR(E19="C",E19=""),0,D19*0.05) -> 0 | G19: =IF(OR(E19="C",E19=""),0,D19*0.07) -> 0 | H19: Groceries | I19: exact | J19: Mexican Hot Sauce | $3.49 BC
A20: 20260214_sobeys_363_95 | B20: 115 | C20: Candy GMS Org | D20: 3.49 | E20: BC | F20: =IF(OR(E20="C",E20=""),0,D20*0.05) -> 0.1745 | G20: =IF(OR(E20="C",E20=""),0,D20*0.07) -> 0.2443 | H20: Groceries | I20: exact | J20: Candy GMS Ors | $3.49 BC
A21: 20260214_sobeys_363_95 | B21: 123 | C21: Candy GMS Org | D21: 3.49 | E21: BC | F21: =IF(OR(E21="C",E21=""),0,D21*0.05) -> 0.1745 | G21: =IF(OR(E21="C",E21=""),0,D21*0.07) -> 0.2443 | H21: Groceries | I21: exact | J21: Candy GMS Or¢ | $3.49 BC
A22: 20260214_sobeys_363_95 | C22: Candy GMS Org | D22: 3.49 | E22: BC | F22: =IF(OR(E22="C",E22=""),0,D22*0.05) -> 0.1745 | G22: =IF(OR(E22="C",E22=""),0,D22*0.07) -> 0.2443
A23: 20260214_sobeys_363_95 | B23: 131 | C23: Lindor 3Pk | D23: 2.99 | E23: BC | F23: =IF(OR(E23="C",E23=""),0,D23*0.05) -> 0.1495 | G23: =IF(OR(E23="C",E23=""),0,D23*0.07) -> 0.2093 | H23: Groceries | I23: default | J23: Lindor 3Pk | $2.99 BC
A24: 20260214_sobeys_363_95 | B24: 135 | C24: Lindor 3Pk | D24: 2.99 | E24: BC | F24: =IF(OR(E24="C",E24=""),0,D24*0.05) -> 0.1495 | G24: =IF(OR(E24="C",E24=""),0,D24*0.07) -> 0.2093 | H24: Groceries | I24: default | J24: Lindor 3Pk | $2.99 BC
A25: 20260214_sobeys_363_95 | B25: 139 | C25: Lindor 3Pk | D25: 2.99 | E25: BC | F25: =IF(OR(E25="C",E25=""),0,D25*0.05) -> 0.1495 | G25: =IF(OR(E25="C",E25=""),0,D25*0.07) -> 0.2093 | H25: Groceries | I25: default | J25: Lindor 3Pk | $2.99 ps
A26: 20260214_sobeys_363_95 | B26: 143 | C26: Chicken Broth | D26: 2.89 | E26: C | F26: =IF(OR(E26="C",E26=""),0,D26*0.05) -> 0 | G26: =IF(OR(E26="C",E26=""),0,D26*0.07) -> 0 | H26: Groceries | I26: exact | J26: Chicken Broth | $2.89
A27: 20260214_sobeys_363_95 | B27: 147 | C27: Bush Baked Beans | D27: 2.5 | E27: C | F27: =IF(OR(E27="C",E27=""),0,D27*0.05) -> 0 | G27: =IF(OR(E27="C",E27=""),0,D27*0.07) -> 0 | H27: Groceries | I27: exact | J27: Bush Baked Beans | $2.50
A28: 20260214_sobeys_363_95 | B28: 157 | C28: Baked Beans | D28: 2.5 | E28: C | F28: =IF(OR(E28="C",E28=""),0,D28*0.05) -> 0 | G28: =IF(OR(E28="C",E28=""),0,D28*0.07) -> 0 | H28: Groceries | I28: exact | J28: Baked Beans | $2.50
A29: 20260214_sobeys_363_95 | B29: 167 | C29: Green Relish | D29: 2.49 | E29: C | F29: =IF(OR(E29="C",E29=""),0,D29*0.05) -> 0 | G29: =IF(OR(E29="C",E29=""),0,D29*0.07) -> 0 | H29: Groceries | I29: default | J29: Green Relish | $2.49
A30: 20260214_sobeys_363_95 | B30: 175 | C30: Cake Mx CarrotSprmst | D30: 2.49 | E30: C | F30: =IF(OR(E30="C",E30=""),0,D30*0.05) -> 0 | G30: =IF(OR(E30="C",E30=""),0,D30*0.07) -> 0 | H30: Groceries | I30: default | J30: Cake Mx CarrotSprimst | $2.49
A31: 20260214_sobeys_363_95 | B31: 185 | C31: Cake Mix French Van | D31: 2.49 | E31: C | F31: =IF(OR(E31="C",E31=""),0,D31*0.05) -> 0 | G31: =IF(OR(E31="C",E31=""),0,D31*0.07) -> 0 | H31: Groceries | I31: default | J31: Cake Mix French Van | $2.49
A32: 20260214_sobeys_363_95 | B32: 193 | C32: Licorice S/Berry | D32: 1.79 | E32: BC | F32: =IF(OR(E32="C",E32=""),0,D32*0.05) -> 0.0895 | G32: =IF(OR(E32="C",E32=""),0,D32*0.07) -> 0.1253 | H32: Groceries | I32: exact | J32: Licorice $/Berry | $1.79 BC
A33: 20260214_sobeys_363_95 | B33: 197 | C33: Licorice S/Berry | D33: 1.79 | E33: BC | F33: =IF(OR(E33="C",E33=""),0,D33*0.05) -> 0.0895 | G33: =IF(OR(E33="C",E33=""),0,D33*0.07) -> 0.1253 | H33: Groceries | I33: exact | J33: Licorice S/Berry | $1.79 BC
A34: 20260214_sobeys_363_95 | B34: 201 | C34: Licorice S/Berry | D34: 1.79 | E34: BC | F34: =IF(OR(E34="C",E34=""),0,D34*0.05) -> 0.0895 | G34: =IF(OR(E34="C",E34=""),0,D34*0.07) -> 0.1253 | H34: Groceries | I34: exact | J34: Licorice S/Berry | $1.79 BC
... A59: 20260214_sobeys_363_95 | B59: 623 | C59: Cheese Slide Med Chd | D59: 15.49 | E59: C | F59: =IF(OR(E59="C",E59=""),0,D59*0.05) -> 0 | G59: =IF(OR(E59="C",E59=""),0,D59*0.07) -> 0 | H59: Groceries | I59: default | J59: DE | $15.49
A60: 20260214_sobeys_363_95 | C60: INSTANT SAVINGS | D60: -1 | F60: =IF(OR(E60="C",E60=""),0,D60*0.05) -> 0 | G60: =IF(OR(E60="C",E60=""),0,D60*0.07) -> 0
A61: 20260214_sobeys_363_95 | B61: 635 | C61: Marble Cheddar | D61: 14.49 | E61: C | F61: =IF(OR(E61="C",E61=""),0,D61*0.05) -> 0 | G61: =IF(OR(E61="C",E61=""),0,D61*0.07) -> 0 | H61: Groceries | I61: default | J61: Marble Cheddar | $14.49
A62: 20260214_sobeys_363_95 | B62: 639 | C62: Cheese Feta Light | D62: 6.99 | E62: C | F62: =IF(OR(E62="C",E62=""),0,D62*0.05) -> 0 | G62: =IF(OR(E62="C",E62=""),0,D62*0.07) -> 0 | H62: Groceries | I62: exact | J62: Cheese Feta Light | $6.99
A63: 20260214_sobeys_363_95 | B63: 643 | C63: Chckn Brst Roast Ckd | D63: 5.46 | E63: C | F63: =IF(OR(E63="C",E63=""),0,D63*0.05) -> 0 | G63: =IF(OR(E63="C",E63=""),0,D63*0.07) -> 0 | H63: Groceries | I63: default | J63: Chekn Brst Roast Ckd | $5.46
A64: 20260214_sobeys_363_95 | B64: 651 | C64: Salami | D64: 4.17 | E64: C | F64: =IF(OR(E64="C",E64=""),0,D64*0.05) -> 0 | G64: =IF(OR(E64="C",E64=""),0,D64*0.07) -> 0 | H64: Groceries | I64: default | J64: Salami | $4.17
...

Sheet Receipts
A1: receipt_id | B1: order_id | C1: receipt_filename | D1: filename_total_cad | E1: subtotal_cad | F1: tax_cad | G1: total_cad | H1: parsed_item_count
A2: 20260214_sobeys_363_95 | B2: 20260214_sobeys_363_95 | C2: 20260214_sobeys_363_95.pdf | D2: 363.95 | G2: 363.95 | H2: 71

Sheet Receipt Category Totals
A1: receipt_id | B1: Child Support | C1: Autopac | D1: Car Payment | E1: Car Repair | F1: Car Replacement Fund | G1: Real Estate Tax | H1: Rental Expenses | I1: Cleaning | J1: Clothing | K1: Debt | L1: Dining | M1: Misc Paul & Rox | N1: Medical ProfSvcs | O1: University / Books | P1: Emergency Fund | Q1: Fuel | R1: Fun / Entertainment | S1: Furniture / Appliances | T1: Birthday / Celebrations | U1: Groceries | V1: IncomeTax Due | W1: Home Insurance | X1: Mortgage PrePayment | Y1: Interest Expense | Z1: Life Insurance | AA1: Medical Products | AB1: LTD Insurance | AC1: Home Mortgage | AD1: Lake | AE1: Sinking Fund | AF1: Donations | AG1: Vacation | AH1: Christmas | AI1: Home Improvement | AJ1: RRSP GIC | AK1: RRSP | AL1: Health & Fitness | AM1: Accounting | AN1: Hydro | AO1: Online Svcs | AP1: Wireless | AQ1: TV | AR1: Water | AS1: Bank Fee | AT1: MLCC | AU1: Cash/Unknown | AV1: Kids Clothing | AW1: Kids Sports | AX1: Emp Reimburse | AY1: Principal Expense | AZ1: Student Expense | BA1: Hair/Salon/Body Care | BB1: Future Use1 | BC1: Indoor Supplies | BD1: Outdoor Supplies | BE1: Future Use2 | BF1: Parking | BG1: Shareholder loan | BH1: TFSA | BI1: Asset Purchase | BJ1: Total
A2: 20260214_sobeys_363_95 | B2: =SUMIFS(Items!$D:$D,Items!$A:$A,$A2,Items!$H:$H,B1) -> 0 | C2: =SUMIFS(Items!$D:$D,Items!$A:$A,$A2,Items!$H:$H,C1) -> 0 | D2: =SUMIFS(Items!$D:$D,Items!$A:$A,$A2,Items!$H:$H,D1) -> 0 | E2: =SUMIFS(Items!$D:$D,Items!$A:$A,$A2,Items!$H:$H,E1) -> 0 | F2: =SUMIFS(Items!$D:$D,Items!$A:$A,$A2,Items!$H:$H,F1) -> 0 | G2: =SUMIFS(Items!$D:$D,Items!$A:$A,$A2,Items!$H:$H,G1) -> 0 | H2: =SUMIFS(Items!$D:$D,Items!$A:$A,$A2,Items!$H:$H,H1) -> 0 | I2: =SUMIFS(Items!$D:$D,Items!$A:$A,$A2,Items!$H:$H,I1) -> 0 | ... BI2: =SUMIFS(Items!$D:$D,Items!$A:$A,$A2,Items!$H:$H,BI1) -> 0 | BJ2: =SUM(B2:BI2) -> 345.05

Sheet Notes
A1: note
A2: Input path: /Users/paul/Developer/home-budget-pipeline/receipts/Sobeys/20260214_sobeys_363_95.pdf
A3: Receipts parsed: 1
A4: Items parsed: 71
A5: AI Status: enabled=True, disabled_runtime=False, calls=0, batch_items=0, ai_cache_hits=1, success=0, api_errors=0.
